Workbook

Sheet Sheet1
A3: Row Labels | B3: Average of yoy_change
A4: Andaman & Nicobar | B4: -0.094
A5: Andhra Pradesh | B5: -2.528
A6: Arunachal Pradesh | B6: 0.026
A7: Assam | B7: 0.64
A8: Bihar | B8: 0.088
A9: Chandigarh | B9: -4.4
A10: Chhattisgarh | B10: 0.75
A11: Dadra & Nagar Haveli and Daman & Diu | B11: 2.62
A12: Delhi | B12: -5.502
A13: Goa | B13: -2.04
A14: Gujarat | B14: -1.588
A15: Haryana | B15: -0.032
... A40: Grand Total | B40: -0.5396

Sheet Sheet2
A1: year | B1: 2025
A3: Row Labels | B3: Average of stage_extraction
A4: Andaman & Nicobar | B4: 2.27
A5: Andhra Pradesh | B5: 31.51
A6: Arunachal Pradesh | B6: 0.41
A7: Assam | B7: 14.45
A8: Bihar | B8: 46.2
A9: Chandigarh | B9: 67
A10: Chhattisgarh | B10: 48.18
A11: Dadra & Nagar Haveli and Daman & Diu | B11: 41.67
A12: Delhi | B12: 92.1
A13: Goa | B13: 23.3
A14: Gujarat | B14: 55.95
A15: Haryana | B15: 136.75
... A40: Grand Total | B40: 48.019167

Sheet Forecast
A1: State | B1: Current Status | C1: Avg Yearly Change | D1: Projected 2027 | E1: Projected 2030 | F1: Forecast_Reliability
A2: Punjab | B2: =VLOOKUP(A2, Sheet2!A:B, 2, FALSE) -> 156.36 | C2: =VLOOKUP(A2,Sheet1!A31:B66,2,FALSE) -> -1.882 | D2: =B2+(C2*2) -> 152.596 | E2: =MAX(0,B2+(C2*5)) -> 146.95 | F2: =IF(OR(A2="Himachal Pradesh", A2="Dadra & Nagar Haveli and Daman & Diu"), "Low confidence - non-linear trend", "Reliable") -> Reliable
A3: Rajasthan | B3: =VLOOKUP(A3, Sheet2!A:B, 2, FALSE) -> 147.11 | C3: =VLOOKUP(A3,Sheet1!A32:B67,2,FALSE) -> 1.446 | D3: =B3+(C3*2) -> 150.002 | E3: =MAX(0,B3+(C3*5)) -> 154.34 | F3: =IF(OR(A3="Himachal Pradesh", A3="Dadra & Nagar Haveli and Daman & Diu"), "Low confidence - non-linear trend", "Reliable") -> Reliable
A4: Haryana | B4: =VLOOKUP(A4, Sheet2!A:B, 2, FALSE) -> 136.75 | C4: =VLOOKUP(A4,Sheet1!A15:B50,2,FALSE) -> -0.032 | D4: =B4+(C4*2) -> 136.686 | E4: =MAX(0,B4+(C4*5)) -> 136.59 | F4: =IF(OR(A4="Himachal Pradesh", A4="Dadra & Nagar Haveli and Daman & Diu"), "Low confidence - non-linear trend", "Reliable") -> Reliable
A5: Delhi | B5: =VLOOKUP(A5, Sheet2!A:B, 2, FALSE) -> 92.1 | C5: =VLOOKUP(A5,Sheet1!A12:B47,2,FALSE) -> -5.502 | D5: =B5+(C5*2) -> 81.096 | E5: =MAX(0,B5+(C5*5)) -> 64.59 | F5: =IF(OR(A5="Himachal Pradesh", A5="Dadra & Nagar Haveli and Daman & Diu"), "Low confidence - non-linear trend", "Reliable") -> Reliable
A6: Puducherry | B6: =VLOOKUP(A6, Sheet2!A:B, 2, FALSE) -> 75.98 | C6: =VLOOKUP(A6,Sheet1!A30:B65,2,FALSE) -> 2.855 | D6: =B6+(C6*2) -> 81.69 | E6: =MAX(0,B6+(C6*5)) -> 90.255 | F6: =IF(OR(A6="Himachal Pradesh", A6="Dadra & Nagar Haveli and Daman & Diu"), "Low confidence - non-linear trend", "Reliable") -> Reliable
A7: Tamil Nadu | B7: =VLOOKUP(A7, Sheet2!A:B, 2, FALSE) -> 73.5 | C7: =VLOOKUP(A7,Sheet1!A34:B69,2,FALSE) -> -1.488 | D7: =B7+(C7*2) -> 70.524 | E7: =MAX(0,B7+(C7*5)) -> 66.06 | F7: =IF(OR(A7="Himachal Pradesh", A7="Dadra & Nagar Haveli and Daman & Diu"), "Low confidence - non-linear trend", "Reliable") -> Reliable
A8: Uttar Pradesh | B8: =VLOOKUP(A8, Sheet2!A:B, 2, FALSE) -> 70 | C8: =VLOOKUP(A8,Sheet1!A37:B72,2,FALSE) -> -0.036 | D8: =B8+(C8*2) -> 69.928 | E8: =MAX(0,B8+(C8*5)) -> 69.82 | F8: =IF(OR(A8="Himachal Pradesh", A8="Dadra & Nagar Haveli and Daman & Diu"), "Low confidence - non-linear trend", "Reliable") -> Reliable
A9: Chandigarh | B9: =VLOOKUP(A9, Sheet2!A:B, 2, FALSE) -> 67 | C9: =VLOOKUP(A9,Sheet1!A9:B44,2,FALSE) -> -4.4 | D9: =B9+(C9*2) -> 58.2 | E9: =MAX(0,B9+(C9*5)) -> 45 | F9: =IF(OR(A9="Himachal Pradesh", A9="Dadra & Nagar Haveli and Daman & Diu"), "Low confidence - non-linear trend", "Reliable") -> Reliable
A10: Karnataka | B10: =VLOOKUP(A10, Sheet2!A:B, 2, FALSE) -> 66.49 | C10: =VLOOKUP(A10,Sheet1!A19:B54,2,FALSE) -> -0.676 | D10: =B10+(C10*2) -> 65.138 | E10: =MAX(0,B10+(C10*5)) -> 63.11 | F10: =IF(OR(A10="Himachal Pradesh", A10="Dadra & Nagar Haveli and Daman & Diu"), "Low confidence - non-linear trend", "Reliable") -> Reliable
A11: Madhya Pradesh | B11: =VLOOKUP(A11, Sheet2!A:B, 2, FALSE) -> 59.32 | C11: =VLOOKUP(A11,Sheet1!A23:B58,2,FALSE) -> 0.912 | D11: =B11+(C11*2) -> 61.144 | E11: =MAX(0,B11+(C11*5)) -> 63.88 | F11: =IF(OR(A11="Himachal Pradesh", A11="Dadra & Nagar Haveli and Daman & Diu"), "Low confidence - non-linear trend", "Reliable") -> Reliable
A12: Lakshadweep | B12: =VLOOKUP(A12, Sheet2!A:B, 2, FALSE) -> 57.79 | C12: =VLOOKUP(A12,Sheet1!A22:B57,2,FALSE) -> -0.17 | D12: =B12+(C12*2) -> 57.45 | E12: =MAX(0,B12+(C12*5)) -> 56.94 | F12: =IF(OR(A12="Himachal Pradesh", A12="Dadra & Nagar Haveli and Daman & Diu"), "Low confidence - non-linear trend", "Reliable") -> Reliable
A13: Gujarat | B13: =VLOOKUP(A13, Sheet2!A:B, 2, FALSE) -> 55.95 | C13: =VLOOKUP(A13,Sheet1!A14:B49,2,FALSE) -> -1.588 | D13: =B13+(C13*2) -> 52.774 | E13: =MAX(0,B13+(C13*5)) -> 48.01 | F13: =IF(OR(A13="Himachal Pradesh", A13="Dadra & Nagar Haveli and Daman & Diu"), "Low confidence - non-linear trend", "Reliable") -> Reliable
A14: Uttarakhand | B14: =VLOOKUP(A14, Sheet2!A:B, 2, FALSE) -> 53.92 | C14: =VLOOKUP(A14,Sheet1!A38:B73,2,FALSE) -> -0.582 | D14: =B14+(C14*2) -> 52.756 | E14: =MAX(0,B14+(C14*5)) -> 51.01 | F14: =IF(OR(A14="Himachal Pradesh", A14="Dadra & Nagar Haveli and Daman & Diu"), "Low confidence - non-linear trend", "Reliable") -> Reliable
A15: Maharashtra | B15: =VLOOKUP(A15, Sheet2!A:B, 2, FALSE) -> 51.79 | C15: =VLOOKUP(A15,Sheet1!A24:B59,2,FALSE) -> -0.566 | D15: =B15+(C15*2) -> 50.658 | E15: =MAX(0,B15+(C15*5)) -> 48.96 | F15: =IF(OR(A15="Himachal Pradesh", A15="Dadra & Nagar Haveli and Daman & Diu"), "Low confidence - non-linear trend", "Reliable") -> Reliable
A16: Kerala | B16: =VLOOKUP(A16, Sheet2!A:B, 2, FALSE) -> 49.95 | C16: =VLOOKUP(A16,Sheet1!A20:B55,2,FALSE) -> -0.264 | D16: =B16+(C16*2) -> 49.422 | E16: =MAX(0,B16+(C16*5)) -> 48.63 | F16: =IF(OR(A16="Himachal Pradesh", A16="Dadra & Nagar Haveli and Daman & Diu"), "Low confidence - non-linear trend", "Reliable") -> Reliable
A17: Odisha | B17: =VLOOKUP(A17, Sheet2!A:B, 2, FALSE) -> 48.75 | C17: =VLOOKUP(A17,Sheet1!A29:B64,2,FALSE) -> 1.314 | D17: =B17+(C17*2) -> 51.378 | E17: =MAX(0,B17+(C17*5)) -> 55.32 | F17: =IF(OR(A17="Himachal Pradesh", A17="Dadra & Nagar Haveli and Daman & Diu"), "Low confidence - non-linear trend", "Reliable") -> Reliable
A18: Chhattisgarh | B18: =VLOOKUP(A18, Sheet2!A:B, 2, FALSE) -> 48.18 | C18: =VLOOKUP(A18,Sheet1!A10:B45,2,FALSE) -> 0.75 | D18: =B18+(C18*2) -> 49.68 | E18: =MAX(0,B18+(C18*5)) -> 51.93 | F18: =IF(OR(A18="Himachal Pradesh", A18="Dadra & Nagar Haveli and Daman & Diu"), "Low confidence - non-linear trend", "Reliable") -> Reliable
A19: Telangana | B19: =VLOOKUP(A19, Sheet2!A:B, 2, FALSE) -> 46.69 | C19: =VLOOKUP(A19,Sheet1!A35:B70,2,FALSE) -> -3.752 | D19: =B19+(C19*2) -> 39.186 | E19: =MAX(0,B19+(C19*5)) -> 27.93 | F19: =IF(OR(A19="Himachal Pradesh", A19="Dadra & Nagar Haveli and Daman & Diu"), "Low confidence - non-linear trend", "Reliable") -> Reliable
A20: Bihar | B20: =VLOOKUP(A20, Sheet2!A:B, 2, FALSE) -> 46.2 | C20: =VLOOKUP(A20,Sheet1!A8:B43,2,FALSE) -> 0.088 | D20: =B20+(C20*2) -> 46.376 | E20: =MAX(0,B20+(C20*5)) -> 46.64 | F20: =IF(OR(A20="Himachal Pradesh", A20="Dadra & Nagar Haveli and Daman & Diu"), "Low confidence - non-linear trend", "Reliable") -> Reliable
A21: West Bengal | B21: =VLOOKUP(A21, Sheet2!A:B, 2, FALSE) -> 45.19 | C21: =VLOOKUP(A21,Sheet1!A39:B74,2,FALSE) -> 0.118 | D21: =B21+(C21*2) -> 45.426 | E21: =MAX(0,B21+(C21*5)) -> 45.78 | F21: =IF(OR(A21="Himachal Pradesh", A21="Dadra & Nagar Haveli and Daman & Diu"), "Low confidence - non-linear trend", "Reliable") -> Reliable
A22: Dadra & Nagar Haveli and Daman & Diu | B22: =VLOOKUP(A22, Sheet2!A:B, 2, FALSE) -> 41.67 | C22: =VLOOKUP(A22,Sheet1!A11:B46,2,FALSE) -> 2.62 | D22: =B22+(C22*2) -> 46.91 | E22: =MAX(0,B22+(C22*5)) -> 54.77 | F22: =IF(OR(A22="Himachal Pradesh", A22="Dadra & Nagar Haveli and Daman & Diu"), "Low confidence - non-linear trend", "Reliable") -> Low confidence - non-linear trend
A23: Himachal Pradesh | B23: =VLOOKUP(A23, Sheet2!A:B, 2, FALSE) -> 38.5 | C23: =VLOOKUP(A23,Sheet1!A16:B51,2,FALSE) -> -9.574 | D23: =B23+(C23*2) -> 19.352 | E23: =MAX(0,B23+(C23*5)) -> 0 | F23: =IF(OR(A23="Himachal Pradesh", A23="Dadra & Nagar Haveli and Daman & Diu"), "Low confidence - non-linear trend", "Reliable") -> Low confidence - non-linear trend
A24: Jharkhand | B24: =VLOOKUP(A24, Sheet2!A:B, 2, FALSE) -> 32.89 | C24: =VLOOKUP(A24,Sheet1!A18:B53,2,FALSE) -> 1.032 | D24: =B24+(C24*2) -> 34.954 | E24: =MAX(0,B24+(C24*5)) -> 38.05 | F24: =IF(OR(A24="Himachal Pradesh", A24="Dadra & Nagar Haveli and Daman & Diu"), "Low confidence - non-linear trend", "Reliable") -> Reliable
A25: Andhra Pradesh | B25: =VLOOKUP(A25, Sheet2!A:B, 2, FALSE) -> 31.51 | C25: =VLOOKUP(A25,Sheet1!A5:B40,2,FALSE) -> -2.528 | D25: =B25+(C25*2) -> 26.454 | E25: =MAX(0,B25+(C25*5)) -> 18.87 | F25: =IF(OR(A25="Himachal Pradesh", A25="Dadra & Nagar Haveli and Daman & Diu"), "Low confidence - non-linear trend", "Reliable") -> Reliable
A26: Ladakh | B26: =VLOOKUP(A26, Sheet2!A:B, 2, FALSE) -> 30.93 | C26: =VLOOKUP(A26,Sheet1!A21:B56,2,FALSE) -> 3.2575 | D26: =B26+(C26*2) -> 37.445 | E26: =MAX(0,B26+(C26*5)) -> 47.2175 | F26: =IF(OR(A26="Himachal Pradesh", A26="Dadra & Nagar Haveli and Daman & Diu"), "Low confidence - non-linear trend", "Reliable") -> Reliable
A27: Jammu & Kashmir | B27: =VLOOKUP(A27, Sheet2!A:B, 2, FALSE) -> 24.73 | C27: =VLOOKUP(A27,Sheet1!A17:B52,2,FALSE) -> -0.948 | D27: =B27+(C27*2) -> 22.834 | E27: =MAX(0,B27+(C27*5)) -> 19.99 | F27: =IF(OR(A27="Himachal Pradesh", A27="Dadra & Nagar Haveli and Daman & Diu"), "Low confidence - non-linear trend", "Reliable") -> Reliable
A28: Goa | B28: =VLOOKUP(A28, Sheet2!A:B, 2, FALSE) -> 23.3 | C28: =VLOOKUP(A28,Sheet1!A13:B48,2,FALSE) -> -2.04 | D28: =B28+(C28*2) -> 19.22 | E28: =MAX(0,B28+(C28*5)) -> 13.1 | F28: =IF(OR(A28="Himachal Pradesh", A28="Dadra & Nagar Haveli and Daman & Diu"), "Low confidence - non-linear trend", "Reliable") -> Reliable
A29: Assam | B29: =VLOOKUP(A29, Sheet2!A:B, 2, FALSE) -> 14.45 | C29: =VLOOKUP(A29,Sheet1!A7:B42,2,FALSE) -> 0.64 | D29: =B29+(C29*2) -> 15.73 | E29: =MAX(0,B29+(C29*5)) -> 17.65 | F29: =IF(OR(A29="Himachal Pradesh", A29="Dadra & Nagar Haveli and Daman & Diu"), "Low confidence - non-linear trend", "Reliable") -> Reliable
A30: Tripura | B30: =VLOOKUP(A30, Sheet2!A:B, 2, FALSE) -> 10.06 | C30: =VLOOKUP(A30,Sheet1!A36:B71,2,FALSE) -> 0.436 | D30: =B30+(C30*2) -> 10.932 | E30: =MAX(0,B30+(C30*5)) -> 12.24 | F30: =IF(OR(A30="Himachal Pradesh", A30="Dadra & Nagar Haveli and Daman & Diu"), "Low confidence - non-linear trend", "Reliable") -> Reliable
A31: Manipur | B31: =VLOOKUP(A31, Sheet2!A:B, 2, FALSE) -> 9.09 | C31: =VLOOKUP(A31,Sheet1!A25:B60,2,FALSE) -> 1.53 | D31: =B31+(C31*2) -> 12.15 | E31: =MAX(0,B31+(C31*5)) -> 16.74 | F31: =IF(OR(A31="Himachal Pradesh", A31="Dadra & Nagar Haveli and Daman & Diu"), "Low confidence - non-linear trend", "Reliable") -> Reliable
A32: Sikkim | B32: =VLOOKUP(A32, Sheet2!A:B, 2, FALSE) -> 5.87 | C32: =VLOOKUP(A32,Sheet1!A33:B68,2,FALSE) -> 1.162 | D32: =B32+(C32*2) -> 8.194 | E32: =MAX(0,B32+(C32*5)) -> 11.68 | F32: =IF(OR(A32="Himachal Pradesh", A32="Dadra & Nagar Haveli and Daman & Diu"), "Low confidence - non-linear trend", "Reliable") -> Reliable
A33: Meghalaya | B33: =VLOOKUP(A33, Sheet2!A:B, 2, FALSE) -> 5.24 | C33: =VLOOKUP(A33,Sheet1!A26:B61,2,FALSE) -> 0.592 | D33: =B33+(C33*2) -> 6.424 | E33: =MAX(0,B33+(C33*5)) -> 8.2 | F33: =IF(OR(A33="Himachal Pradesh", A33="Dadra & Nagar Haveli and Daman & Diu"), "Low confidence - non-linear trend", "Reliable") -> Reliable
A34: Nagaland | B34: =VLOOKUP(A34, Sheet2!A:B, 2, FALSE) -> 4.72 | C34: =VLOOKUP(A34,Sheet1!A28:B63,2,FALSE) -> 0.746 | D34: =B34+(C34*2) -> 6.212 | E34: =MAX(0,B34+(C34*5)) -> 8.45 | F34: =IF(OR(A34="Himachal Pradesh", A34="Dadra & Nagar Haveli and Daman & Diu"), "Low confidence - non-linear trend", "Reliable") -> Reliable
A35: Mizoram | B35: =VLOOKUP(A35, Sheet2!A:B, 2, FALSE) -> 4.03 | C35: =VLOOKUP(A35,Sheet1!A27:B62,2,FALSE) -> 0.042 | D35: =B35+(C35*2) -> 4.114 | E35: =MAX(0,B35+(C35*5)) -> 4.24 | F35: =IF(OR(A35="Himachal Pradesh", A35="Dadra & Nagar Haveli and Daman & Diu"), "Low confidence - non-linear trend", "Reliable") -> Reliable
A36: Andaman & Nicobar | B36: =VLOOKUP(A36,Sheet2!A4:B39,2,FALSE) -> 2.27 | C36: =VLOOKUP(A36,Sheet1!A4:B39,2,FALSE) -> -0.094 | D36: =B36+(C36*2) -> 2.082 | E36: =MAX(0,B36+(C36*5)) -> 1.8 | F36: =IF(OR(A36="Himachal Pradesh", A36="Dadra & Nagar Haveli and Daman & Diu"), "Low confidence - non-linear trend", "Reliable") -> Reliable
A37: Arunachal Pradesh | B37: =VLOOKUP(A37, Sheet2!A:B, 2, FALSE) -> 0.41 | C37: =VLOOKUP(A37,Sheet1!A6:B41,2,FALSE) -> 0.026 | D37: =B37+(C37*2) -> 0.462 | E37: =MAX(0,B37+(C37*5)) -> 0.54 | F37: =IF(OR(A37="Himachal Pradesh", A37="Dadra & Nagar Haveli and Daman & Diu"), "Low confidence - non-linear trend", "Reliable") -> Reliable

Sheet state's trend over years
A1: state | B1: year | C1: stage_extraction | D1: prev_stage_extraction | E1: yoy_change | F1: stress_rank
A2: Andaman & Nicobar | B2: 2017 | C2: 2.74 | F2: 28 | J2: {=_xlfn.UNIQUE(A2:A212)} -> Andaman & Nicobar
A3: Andaman & Nicobar | B3: 2020 | C3: 2.6 | D3: 2.74 | E3: -0.14 | F3: 32 | J3: Andhra Pradesh
A4: Andaman & Nicobar | B4: 2022 | C4: 1.35 | D4: 2.6 | E4: -1.25 | F4: 34 | J4: Arunachal Pradesh
A5: Andaman & Nicobar | B5: 2023 | C5: 1.37 | D5: 1.35 | E5: 0.02 | F5: 35 | J5: Assam
A6: Andaman & Nicobar | B6: 2024 | C6: 2.08 | D6: 1.37 | E6: 0.71 | F6: 35 | J6: Bihar
A7: Andaman & Nicobar | B7: 2025 | C7: 2.27 | D7: 2.08 | E7: 0.19 | F7: 35 | J7: Chandigarh
A8: Andhra Pradesh | B8: 2017 | C8: 44.15 | F8: 19 | J8: Chhattisgarh
A9: Andhra Pradesh | B9: 2020 | C9: 33.26 | D9: 44.15 | E9: -10.89 | F9: 22 | J9: Dadra & Nagar Haveli and Daman & Diu
A10: Andhra Pradesh | B10: 2022 | C10: 28.81 | D10: 33.26 | E10: -4.45 | F10: 24 | J10: Delhi
A11: Andhra Pradesh | B11: 2023 | C11: 28.3 | D11: 28.81 | E11: -0.51 | F11: 25 | J11: Goa
A12: Andhra Pradesh | B12: 2024 | C12: 29.83 | D12: 28.3 | E12: 1.53 | F12: 25 | J12: Gujarat
A13: Andhra Pradesh | B13: 2025 | C13: 31.51 | D13: 29.83 | E13: 1.68 | F13: 24 | J13: Haryana
A14: Arunachal Pradesh | B14: 2017 | C14: 0.28 | F14: 32 | J14: Himachal Pradesh
A15: Arunachal Pradesh | B15: 2020 | C15: 0.36 | D15: 0.28 | E15: 0.08 | F15: 35 | J15: Jammu & Kashmir
A16: Arunachal Pradesh | B16: 2022 | C16: 0.79 | D16: 0.36 | E16: 0.43 | F16: 35 | J16: Jharkhand
A17: Arunachal Pradesh | B17: 2023 | C17: 0.42 | D17: 0.79 | E17: -0.37 | F17: 36 | J17: Karnataka
A18: Arunachal Pradesh | B18: 2024 | C18: 0.39 | D18: 0.42 | E18: -0.03 | F18: 36 | J18: Kerala
A19: Arunachal Pradesh | B19: 2025 | C19: 0.41 | D19: 0.39 | E19: 0.02 | F19: 36 | J19: Ladakh
A20: Assam | B20: 2017 | C20: 11.25 | F20: 25 | J20: Lakshadweep
A21: Assam | B21: 2020 | C21: 11.73 | D21: 11.25 | E21: 0.48 | F21: 27 | J21: Madhya Pradesh
A22: Assam | B22: 2022 | C22: 12.38 | D22: 11.73 | E22: 0.65 | F22: 27 | J22: Maharashtra
A23: Assam | B23: 2023 | C23: 12.54 | D23: 12.38 | E23: 0.16 | F23: 28 | J23: Manipur
A24: Assam | B24: 2024 | C24: 12.61 | D24: 12.54 | E24: 0.07 | F24: 28 | J24: Meghalaya
A25: Assam | B25: 2025 | C25: 14.45 | D25: 12.61 | E25: 1.84 | F25: 28 | J25: Mizoram
A26: Bihar | B26: 2017 | C26: 45.76 | F26: 16 | J26: Nagaland
A27: Bihar | B27: 2020 | C27: 51.14 | D27: 45.76 | E27: 5.38 | F27: 16 | J27: Odisha
A28: Bihar | B28: 2022 | C28: 44.94 | D28: 51.14 | E28: -6.2 | F28: 18 | J28: Puducherry
A29: Bihar | B29: 2023 | C29: 44.76 | D29: 44.94 | E29: -0.18 | F29: 20 | J29: Punjab
A30: Bihar | B30: 2024 | C30: 45.54 | D30: 44.76 | E30: 0.78 | F30: 21 | J30: Rajasthan
A31: Bihar | B31: 2025 | C31: 46.2 | D31: 45.54 | E31: 0.66 | F31: 19 | J31: Sikkim
A32: Chandigarh | B32: 2017 | C32: 89 | F32: 5 | J32: Tamil Nadu
A33: Chandigarh | B33: 2020 | C33: 80.6 | D33: 89 | E33: -8.4 | F33: 6 | J33: Telangana
A34: Chandigarh | B34: 2022 | C34: 80.99 | D34: 80.6 | E34: 0.39 | F34: 6 | J34: Tripura
A35: Chandigarh | B35: 2023 | C35: 75.41 | D35: 80.99 | E35: -5.58 | F35: 6 | J35: Uttar Pradesh
A36: Chandigarh | B36: 2024 | C36: 66.13 | D36: 75.41 | E36: -9.28 | F36: 10 | J36: Uttarakhand
A37: Chandigarh | B37: 2025 | C37: 67 | D37: 66.13 | E37: 0.87 | F37: 8 | J37: West Bengal
A38: Chhattisgarh | B38: 2017 | C38: 44.43 | F38: 18
A39: Chhattisgarh | B39: 2020 | C39: 46.34 | D39: 44.43 | E39: 1.91 | F39: 18
A40: Chhattisgarh | B40: 2022 | C40: 49.58 | D40: 46.34 | E40: 3.24 | F40: 15
...
